Workbook
Name _Int_h0KAy7bb: '2a. Administration'!$B$9
Name _Int_h0KAy7bb: '2b. Planning'!$B$7
Name _Int_h0KAy7bb: '2c. Delivery'!$B$9
Name _Int_h0KAy7bb: '2d. Reconciliation'!$B$9
Name _Int_h0KAy7bb: '2e. Reporting'!$B$9
Name _Int_h0KAy7bb: '3a. Security'!#REF!
Name _Int_h0KAy7bb: '3b. User Interface and User Exp'!#REF!
Name _Int_h0KAy7bb: '3c. Performance-Scalability'!#REF!
Name _Int_h0KAy7bb: '3d. Support-Maintenance'!#REF!
Name _Int_h0KAy7bb: '3e. Reliability-Availability'!#REF!
Name _Int_h0KAy7bb: '3f. Integration'!#REF!
Name _Int_h0KAy7bb: '3g. Configurability'!#REF!
Name _Int_h0KAy7bb: '3h. Compliance'!#REF!
Name _Int_QiuZ3ikt: '2b. Planning'!$C$24
Name _Int_QiuZ3ikt: '2c. Delivery'!$C$33
Name _Int_QiuZ3ikt: '2d. Reconciliation'!#REF!
Name _Int_QiuZ3ikt: '2e. Reporting'!#REF!
Name _Int_QiuZ3ikt: '3a. Security'!#REF!
Name _Int_QiuZ3ikt: '3b. User Interface and User Exp'!#REF!
Name _Int_QiuZ3ikt: '3c. Performance-Scalability'!#REF!
Name _Int_QiuZ3ikt: '3d. Support-Maintenance'!#REF!
Name _Int_QiuZ3ikt: '3e. Reliability-Availability'!#REF!
Name _Int_QiuZ3ikt: '3f. Integration'!#REF!
Name _Int_QiuZ3ikt: '3g. Configurability'!#REF!
Name _Int_QiuZ3ikt: '3h. Compliance'!#REF!

Sheet Summary
A1: Requirements | C1: SX | D1: X | F1: SX | G1: X
A2: # | B2: Item | C2: Critical | D2: Non Critical | E2: Total | F2: Critical | G2: Non Critical | H2: Total | I2: Delta
A3: 2a | B3: Administration | C3: =COUNTIFS('2a. Administration'!$I:$I,Summary!$A3,'2a. Administration'!$E:$E,Summary!C1) -> 68 | D3: =COUNTIFS('2a. Administration'!$I:$I,Summary!$A3,'2a. Administration'!$E:$E,Summary!D1) -> 19 | E3: =SUM(C3:D3) -> 87 | F3: =COUNTIFS('2a. Administration'!$I:$I,Summary!$A3,'2a. Administration'!$G:$G,Summary!F1) -> 49 | G3: =COUNTIFS('2a. Administration'!$I:$I,Summary!$A3,'2a. Administration'!$G:$G,Summary!G1) -> 8 | H3: =SUM(F3:G3) -> 57 | I3: =H3-E3 -> -30
A4: 2b | B4: Planning | C4: =COUNTIFS('2b. Planning'!$I:$I,Summary!$A4,'2b. Planning'!$E:$E,Summary!C1) -> 155 | D4: =COUNTIFS('2b. Planning'!$I:$I,Summary!$A4,'2b. Planning'!$E:$E,Summary!D1) -> 97 | E4: =SUM(C4:D4) -> 252 | F4: =COUNTIFS('2b. Planning'!$I:$I,Summary!$A4,'2b. Planning'!$G:$G,Summary!F1) -> 118 | G4: =COUNTIFS('2b. Planning'!$I:$I,Summary!$A4,'2b. Planning'!$G:$G,Summary!G1) -> 44 | H4: =SUM(F4:G4) -> 162 | I4: =H4-E4 -> -90
A5: 2c | B5: Delivery | C5: =COUNTIFS('2c. Delivery'!$I:$I,Summary!$A5,'2c. Delivery'!$E:$E,Summary!C1) -> 27 | D5: =COUNTIFS('2c. Delivery'!$I:$I,Summary!$A5,'2c. Delivery'!$E:$E,Summary!D1) -> 74 | E5: =SUM(C5:D5) -> 101 | F5: =COUNTIFS('2c. Delivery'!$I:$I,Summary!$A5,'2c. Delivery'!$G:$G,Summary!F1) -> 21 | G5: =COUNTIFS('2c. Delivery'!$I:$I,Summary!$A5,'2c. Delivery'!$G:$G,Summary!G1) -> 38 | H5: =SUM(F5:G5) -> 59 | I5: =H5-E5 -> -42
A6: 2d | B6: Reconciliation | C6: =COUNTIFS('2d. Reconciliation'!$I:$I,Summary!$A6,'2d. Reconciliation'!$E:$E,Summary!C1) -> 17 | D6: =COUNTIFS('2d. Reconciliation'!$I:$I,Summary!$A6,'2d. Reconciliation'!$E:$E,Summary!D1) -> 13 | E6: =SUM(C6:D6) -> 30 | F6: =COUNTIFS('2d. Reconciliation'!$I:$I,Summary!$A6,'2d. Reconciliation'!$G:$G,Summary!F1) -> 12 | G6: =COUNTIFS('2d. Reconciliation'!$I:$I,Summary!$A6,'2d. Reconciliation'!$G:$G,Summary!G1) -> 7 | H6: =SUM(F6:G6) -> 19 | I6: =H6-E6 -> -11
A7: 2e | B7: Reporting | C7: =COUNTIFS('2e. Reporting'!$I:$I,Summary!$A7,'2e. Reporting'!$E:$E,Summary!C1) -> 49 | D7: =COUNTIFS('2e. Reporting'!$I:$I,Summary!$A7,'2e. Reporting'!$E:$E,Summary!D1) -> 25 | E7: =SUM(C7:D7) -> 74 | F7: =COUNTIFS('2e. Reporting'!$I:$I,Summary!$A7,'2e. Reporting'!$G:$G,Summary!F1) -> 49 | G7: =COUNTIFS('2e. Reporting'!$I:$I,Summary!$A7,'2e. Reporting'!$G:$G,Summary!G1) -> 19 | H7: =SUM(F7:G7) -> 68 | I7: =H7-E7 -> -6
A9: 3a | B9: Security | C9: =COUNTIFS('3a. Security'!$I:$I,Summary!$A9,'3a. Security'!$E:$E,Summary!C1) -> 6 | D9: =COUNTIFS('3a. Security'!$I:$I,Summary!$A9,'3a. Security'!$E:$E,Summary!D1) -> 0 | E9: =SUM(C9:D9) -> 6 | F9: =COUNTIFS('3a. Security'!$I:$I,Summary!$A9,'3a. Security'!$G:$G,Summary!F1) -> 6 | G9: =COUNTIFS('3a. Security'!$I:$I,Summary!$A9,'3a. Security'!$G:$G,Summary!G1) -> 0 | H9: =SUM(F9:G9) -> 6 | I9: =H9-E9 -> 0
A10: 3b | B10: User Interface & User Exp | C10: =COUNTIFS('3b. User Interface and User Exp'!$I:$I,Summary!$A10,'3b. User Interface and User Exp'!$E:$E,Summary!C1) -> 2 | D10: =COUNTIFS('3b. User Interface and User Exp'!$I:$I,Summary!$A10,'3b. User Interface and User Exp'!$E:$E,Summary!D1) -> 5 | E10: =SUM(C10:D10) -> 7 | F10: =COUNTIFS('3b. User Interface and User Exp'!$I:$I,Summary!$A10,'3b. User Interface and User Exp'!$G:$G,Summary!F1) -> 2 | G10: =COUNTIFS('3b. User Interface and User Exp'!$I:$I,Summary!$A10,'3b. User Interface and User Exp'!$G:$G,Summary!G1) -> 5 | H10: =SUM(F10:G10) -> 7 | I10: =H10-E10 -> 0
A11: 3c | B11: Performance & Scalability | C11: =COUNTIFS('3c. Performance-Scalability'!$I:$I,Summary!$A11,'3c. Performance-Scalability'!$E:$E,Summary!C1) -> 0 | D11: =COUNTIFS('3c. Performance-Scalability'!$I:$I,Summary!$A11,'3c. Performance-Scalability'!$E:$E,Summary!D1) -> 6 | E11: =SUM(C11:D11) -> 6 | F11: =COUNTIFS('3c. Performance-Scalability'!$I:$I,Summary!$A11,'3c. Performance-Scalability'!$G:$G,Summary!F1) -> 0 | G11: =COUNTIFS('3c. Performance-Scalability'!$I:$I,Summary!$A11,'3c. Performance-Scalability'!$G:$G,Summary!G1) -> 6 | H11: =SUM(F11:G11) -> 6 | I11: =H11-E11 -> 0
A12: 3d | B12: Support-Maintenance | C12: =COUNTIFS('3d. Support-Maintenance'!$I:$I,Summary!$A12,'3d. Support-Maintenance'!$E:$E,Summary!C1) -> 5 | D12: =COUNTIFS('3d. Support-Maintenance'!$I:$I,Summary!$A12,'3d. Support-Maintenance'!$E:$E,Summary!D1) -> 2 | E12: =SUM(C12:D12) -> 7 | F12: =COUNTIFS('3d. Support-Maintenance'!$I:$I,Summary!$A12,'3d. Support-Maintenance'!$G:$G,Summary!F1) -> 5 | G12: =COUNTIFS('3d. Support-Maintenance'!$I:$I,Summary!$A12,'3d. Support-Maintenance'!$G:$G,Summary!G1) -> 2 | H12: =SUM(F12:G12) -> 7 | I12: =H12-E12 -> 0
A13: 3e | B13: Reliability-Availability | C13: =COUNTIFS('3e. Reliability-Availability'!$I:$I,Summary!$A13,'3e. Reliability-Availability'!$E:$E,Summary!C1) -> 4 | D13: =COUNTIFS('3e. Reliability-Availability'!$I:$I,Summary!$A13,'3e. Reliability-Availability'!$E:$E,Summary!D1) -> 4 | E13: =SUM(C13:D13) -> 8 | F13: =COUNTIFS('3e. Reliability-Availability'!$I:$I,Summary!$A13,'3e. Reliability-Availability'!$G:$G,Summary!F1) -> 4 | G13: =COUNTIFS('3e. Reliability-Availability'!$I:$I,Summary!$A13,'3e. Reliability-Availability'!$G:$G,Summary!G1) -> 4 | H13: =SUM(F13:G13) -> 8 | I13: =H13-E13 -> 0
A14: 3f | B14: Integration | C14: =COUNTIFS('3f. Integration'!$I:$I,Summary!$A14,'3f. Integration'!$E:$E,Summary!C1) -> 12 | D14: =COUNTIFS('3f. Integration'!$I:$I,Summary!$A14,'3f. Integration'!$E:$E,Summary!D1) -> 5 | E14: =SUM(C14:D14) -> 17 | F14: =COUNTIFS('3f. Integration'!$I:$I,Summary!$A14,'3f. Integration'!$G:$G,Summary!F1) -> 12 | G14: =COUNTIFS('3f. Integration'!$I:$I,Summary!$A14,'3f. Integration'!$G:$G,Summary!G1) -> 4 | H14: =SUM(F14:G14) -> 16 | I14: =H14-E14 -> -1
A15: 3g | B15: Configurability | C15: =COUNTIFS('3g. Configurability'!$I:$I,Summary!$A15,'3g. Configurability'!$E:$E,Summary!C1) -> 3 | D15: =COUNTIFS('3g. Configurability'!$I:$I,Summary!$A15,'3g. Configurability'!$E:$E,Summary!D1) -> 1 | E15: =SUM(C15:D15) -> 4 | F15: =COUNTIFS('3g. Configurability'!$I:$I,Summary!$A15,'3g. Configurability'!$G:$G,Summary!F1) -> 3 | G15: =COUNTIFS('3g. Configurability'!$I:$I,Summary!$A15,'3g. Configurability'!$G:$G,Summary!G1) -> 1 | H15: =SUM(F15:G15) -> 4 | I15: =H15-E15 -> 0
A16: 3h | B16: Compliance | C16: =COUNTIFS('3h. Compliance'!$I:$I,Summary!$A16,'3h. Compliance'!$E:$E,Summary!C1) -> 4 | D16: =COUNTIFS('3h. Compliance'!$I:$I,Summary!$A16,'3h. Compliance'!$E:$E,Summary!D1) -> 3 | E16: =SUM(C16:D16) -> 7 | F16: =COUNTIFS('3h. Compliance'!$I:$I,Summary!$A16,'3h. Compliance'!$G:$G,Summary!F1) -> 4 | G16: =COUNTIFS('3h. Compliance'!$I:$I,Summary!$A16,'3h. Compliance'!$G:$G,Summary!G1) -> 3 | H16: =SUM(F16:G16) -> 7 | I16: =H16-E16 -> 0
B17: Total | C17: =SUM(C3:C16) -> 352 | D17: =SUM(D3:D16) -> 254 | E17: =SUM(E3:E16) -> 606 | F17: =SUM(F3:F16) -> 285 | G17: =SUM(G3:G16) -> 141 | H17: =SUM(H3:H16) -> 426 | I17: =SUM(I3:I16) -> -180
C19: Y | D19: N | E19: P | F19: Y | G19: N | H19: P | I19: Y | J19: N | K19: P | L19: Y | M19: N | N19: P | O19: Y | P19: N | Q19: P | R19: Y | S19: N | T19: P | U19: Y | V19: N | W19: P
A20: # | B20: Item | C20: Critical | F20: Non Critical | I20: Total | L20: Critical | O20: Non Critical | R20: Total | U20: Delta
A21: 2a | B21: Administration | C21: =COUNTIFS('2a. Administration'!$I:$I,Summary!$A21,'2a. Administration'!$C:$C,Summary!C$19,'2a. Administration'!$E:$E,Summary!$C$1) -> 68 | D21: =COUNTIFS('2a. Administration'!$I:$I,Summary!$A21,'2a. Administration'!$C:$C,Summary!D$19,'2a. Administration'!$E:$E,Summary!$C$1) -> 0 | E21: =COUNTIFS('2a. Administration'!$I:$I,Summary!$A21,'2a. Administration'!$C:$C,Summary!E$19,'2a. Administration'!$E:$E,Summary!$C$1) -> 0 | F21: =COUNTIFS('2a. Administration'!$I:$I,Summary!$A21,'2a. Administration'!$C:$C,Summary!F$19,'2a. Administration'!$E:$E,Summary!$D$1) -> 16 | G21: =COUNTIFS('2a. Administration'!$I:$I,Summary!$A21,'2a. Administration'!$C:$C,Summary!G$19,'2a. Administration'!$E:$E,Summary!$D$1) -> 0 | H21: =COUNTIFS('2a. Administration'!$I:$I,Summary!$A21,'2a. Administration'!$C:$C,Summary!H$19,'2a. Administration'!$E:$E,Summary!$D$1) -> 3 | I21: =C21+F21 -> 84 | J21: =D21+G21 -> 0 | K21: =H21+E21 -> 3 | L21: =COUNTIFS('2a. Administration'!$I:$I,Summary!$A21,'2a. Administration'!$J:$J,Summary!L$19,'2a. Administration'!$E:$E,Summary!$C$1) -> 50 | M21: =COUNTIFS('2a. Administration'!$I:$I,Summary!$A21,'2a. Administration'!$J:$J,Summary!M$19,'2a. Administration'!$E:$E,Summary!$C$1) -> 0 | N21: =COUNTIFS('2a. Administration'!$I:$I,Summary!$A21,'2a. Administration'!$J:$J,Summary!N$19,'2a. Administration'!$E:$E,Summary!$C$1) -> 0 | O21: =COUNTIFS('2a. Administration'!$I:$I,Summary!$A21,'2a. Administration'!$J:$J,Summary!O$19,'2a. Administration'!$E:$E,Summary!$D$1) -> 7 | P21: =COUNTIFS('2a. Administration'!$I:$I,Summary!$A21,'2a. Administration'!$J:$J,Summary!P$19,'2a. Administration'!$E:$E,Summary!$D$1) -> 0 | Q21: =COUNTIFS('2a. Administration'!$I:$I,Summary!$A21,'2a. Administration'!$J:$J,Summary!Q$19,'2a. Administration'!$E:$E,Summary!$D$1) -> 0 | R21: =L21+O21 -> 57 | S21: =M21+P21 -> 0 | T21: =Q21+N21 -> 0 | U21: =R21-I21 -> -27 | V21: =S21-J21 -> 0 | W21: =T21-K21 -> -3
A22: 2b | B22: Planning | C22: =COUNTIFS('2b. Planning'!$I:$I,Summary!$A22,'2b. Planning'!$C:$C,Summary!C$19,'2b. Planning'!$E:$E,Summary!$C$1) -> 155 | D22: =COUNTIFS('2b. Planning'!$I:$I,Summary!$A22,'2b. Planning'!$C:$C,Summary!D$19,'2b. Planning'!$E:$E,Summary!$C$1) -> 0 | E22: =COUNTIFS('2b. Planning'!$I:$I,Summary!$A22,'2b. Planning'!$C:$C,Summary!E$19,'2b. Planning'!$E:$E,Summary!$C$1) -> 0 | F22: =COUNTIFS('2b. Planning'!$I:$I,Summary!$A22,'2b. Planning'!$C:$C,Summary!F$19,'2b. Planning'!$E:$E,Summary!$D$1) -> 49 | G22: =COUNTIFS('2b. Planning'!$I:$I,Summary!$A22,'2b. Planning'!$C:$C,Summary!G$19,'2b. Planning'!$E:$E,Summary!$D$1) -> 2 | H22: =COUNTIFS('2b. Planning'!$I:$I,Summary!$A22,'2b. Planning'!$C:$C,Summary!H$19,'2b. Planning'!$E:$E,Summary!$D$1) -> 46 | I22: =C22+F22 -> 204 | J22: =D22+G22 -> 2 | K22: =H22+E22 -> 46 | L22: =COUNTIFS('2b. Planning'!$I:$I,Summary!$A22,'2b. Planning'!$J:$J,Summary!L$19,'2b. Planning'!$E:$E,Summary!$C$1) -> 122 | M22: =COUNTIFS('2b. Planning'!$I:$I,Summary!$A22,'2b. Planning'!$J:$J,Summary!M$19,'2b. Planning'!$E:$E,Summary!$C$1) -> 0 | N22: =COUNTIFS('2b. Planning'!$I:$I,Summary!$A22,'2b. Planning'!$J:$J,Summary!N$19,'2b. Planning'!$E:$E,Summary!$C$1) -> 0 | O22: =COUNTIFS('2b. Planning'!$I:$I,Summary!$A22,'2b. Planning'!$J:$J,Summary!O$19,'2b. Planning'!$E:$E,Summary!$D$1) -> 39 | P22: =COUNTIFS('2b. Planning'!$I:$I,Summary!$A22,'2b. Planning'!$J:$J,Summary!P$19,'2b. Planning'!$E:$E,Summary!$D$1) -> 0 | Q22: =COUNTIFS('2b. Planning'!$I:$I,Summary!$A22,'2b. Planning'!$J:$J,Summary!Q$19,'2b. Planning'!$E:$E,Summary!$D$1) -> 0 | R22: =L22+O22 -> 161 | S22: =M22+P22 -> 0 | T22: =Q22+N22 -> 0 | U22: =R22-I22 -> -43 | V22: =S22-J22 -> -2 | W22: =T22-K22 -> -46
A23: 2c | B23: Delivery | C23: =COUNTIFS('2c. Delivery'!$I:$I,Summary!$A23,'2c. Delivery'!$C:$C,Summary!C$19,'2c. Delivery'!$E:$E,Summary!$C$1) -> 27 | D23: =COUNTIFS('2c. Delivery'!$I:$I,Summary!$A23,'2c. Delivery'!$C:$C,Summary!D$19,'2c. Delivery'!$E:$E,Summary!$C$1) -> 0 | E23: =COUNTIFS('2c. Delivery'!$I:$I,Summary!$A23,'2c. Delivery'!$C:$C,Summary!E$19,'2c. Delivery'!$E:$E,Summary!$C$1) -> 0 | F23: =COUNTIFS('2c. Delivery'!$I:$I,Summary!$A23,'2c. Delivery'!$C:$C,Summary!F$19,'2c. Delivery'!$E:$E,Summary!$D$1) -> 56 | G23: =COUNTIFS('2c. Delivery'!$I:$I,Summary!$A23,'2c. Delivery'!$C:$C,Summary!G$19,'2c. Delivery'!$E:$E,Summary!$D$1) -> 2 | H23: =COUNTIFS('2c. Delivery'!$I:$I,Summary!$A23,'2c. Delivery'!$C:$C,Summary!H$19,'2c. Delivery'!$E:$E,Summary!$D$1) -> 16 | I23: =C23+F23 -> 83 | J23: =D23+G23 -> 2 | K23: =H23+E23 -> 16 | L23: =COUNTIFS('2c. Delivery'!$I:$I,Summary!$A23,'2c. Delivery'!$J:$J,Summary!L$19,'2c. Delivery'!$E:$E,Summary!$C$1) -> 20 | M23: =COUNTIFS('2c. Delivery'!$I:$I,Summary!$A23,'2c. Delivery'!$J:$J,Summary!M$19,'2c. Delivery'!$E:$E,Summary!$C$1) -> 0 | N23: =COUNTIFS('2c. Delivery'!$I:$I,Summary!$A23,'2c. Delivery'!$J:$J,Summary!N$19,'2c. Delivery'!$E:$E,Summary!$C$1) -> 1 | O23: =COUNTIFS('2c. Delivery'!$I:$I,Summary!$A23,'2c. Delivery'!$J:$J,Summary!O$19,'2c. Delivery'!$E:$E,Summary!$D$1) -> 34 | P23: =COUNTIFS('2c. Delivery'!$I:$I,Summary!$A23,'2c. Delivery'!$J:$J,Summary!P$19,'2c. Delivery'!$E:$E,Summary!$D$1) -> 0 | Q23: =COUNTIFS('2c. Delivery'!$I:$I,Summary!$A23,'2c. Delivery'!$J:$J,Summary!Q$19,'2c. Delivery'!$E:$E,Summary!$D$1) -> 3 | R23: =L23+O23 -> 54 | S23: =M23+P23 -> 0 | T23: =Q23+N23 -> 4 | U23: =R23-I23 -> -29 | V23: =S23-J23 -> -2 | W23: =T23-K23 -> -12
A24: 2d | B24: Reconciliation | C24: =COUNTIFS('2d. Reconciliation'!$I:$I,Summary!$A24,'2d. Reconciliation'!$C:$C,Summary!C$19,'2d. Reconciliation'!$E:$E,Summary!$C$1) -> 17 | D24: =COUNTIFS('2d. Reconciliation'!$I:$I,Summary!$A24,'2d. Reconciliation'!$C:$C,Summary!D$19,'2d. Reconciliation'!$E:$E,Summary!$C$1) -> 0 | E24: =COUNTIFS('2d. Reconciliation'!$I:$I,Summary!$A24,'2d. Reconciliation'!$C:$C,Summary!E$19,'2d. Reconciliation'!$E:$E,Summary!$C$1) -> 0 | F24: =COUNTIFS('2d. Reconciliation'!$I:$I,Summary!$A24,'2d. Reconciliation'!$C:$C,Summary!F$19,'2d. Reconciliation'!$E:$E,Summary!$D$1) -> 9 | G24: =COUNTIFS('2d. Reconciliation'!$I:$I,Summary!$A24,'2d. Reconciliation'!$C:$C,Summary!G$19,'2d. Reconciliation'!$E:$E,Summary!$D$1) -> 0 | H24: =COUNTIFS('2d. Reconciliation'!$I:$I,Summary!$A24,'2d. Reconciliation'!$C:$C,Summary!H$19,'2d. Reconciliation'!$E:$E,Summary!$D$1) -> 4 | I24: =C24+F24 -> 26 | J24: =D24+G24 -> 0 | K24: =H24+E24 -> 4 | L24: =COUNTIFS('2d. Reconciliation'!$I:$I,Summary!$A24,'2d. Reconciliation'!$J:$J,Summary!L$19,'2d. Reconciliation'!$E:$E,Summary!$C$1) -> 12 | M24: =COUNTIFS('2d. Reconciliation'!$I:$I,Summary!$A24,'2d. Reconciliation'!$J:$J,Summary!M$19,'2d. Reconciliation'!$E:$E,Summary!$C$1) -> 0 | N24: =COUNTIFS('2d. Reconciliation'!$I:$I,Summary!$A24,'2d. Reconciliation'!$J:$J,Summary!N$19,'2d. Reconciliation'!$E:$E,Summary!$C$1) -> 0 | O24: =COUNTIFS('2d. Reconciliation'!$I:$I,Summary!$A24,'2d. Reconciliation'!$J:$J,Summary!O$19,'2d. Reconciliation'!$E:$E,Summary!$D$1) -> 7 | P24: =COUNTIFS('2d. Reconciliation'!$I:$I,Summary!$A24,'2d. Reconciliation'!$J:$J,Summary!P$19,'2d. Reconciliation'!$E:$E,Summary!$D$1) -> 0 | Q24: =COUNTIFS('2d. Reconciliation'!$I:$I,Summary!$A24,'2d. Reconciliation'!$J:$J,Summary!Q$19,'2d. Reconciliation'!$E:$E,Summary!$D$1) -> 0 | R24: =L24+O24 -> 19 | S24: =M24+P24 -> 0 | T24: =Q24+N24 -> 0 | U24: =R24-I24 -> -7 | V24: =S24-J24 -> 0 | W24: =T24-K24 -> -4
A25: 2e | B25: Reporting | C25: =COUNTIFS('2e. Reporting'!$I:$I,Summary!$A25,'2e. Reporting'!$C:$C,Summary!C$19,'2e. Reporting'!$E:$E,Summary!$C$1) -> 49 | D25: =COUNTIFS('2e. Reporting'!$I:$I,Summary!$A25,'2e. Reporting'!$C:$C,Summary!D$19,'2e. Reporting'!$E:$E,Summary!$C$1) -> 0 | E25: =COUNTIFS('2e. Reporting'!$I:$I,Summary!$A25,'2e. Reporting'!$C:$C,Summary!E$19,'2e. Reporting'!$E:$E,Summary!$C$1) -> 0 | F25: =COUNTIFS('2e. Reporting'!$I:$I,Summary!$A25,'2e. Reporting'!$C:$C,Summary!F$19,'2e. Reporting'!$E:$E,Summary!$D$1) -> 17 | G25: =COUNTIFS('2e. Reporting'!$I:$I,Summary!$A25,'2e. Reporting'!$C:$C,Summary!G$19,'2e. Reporting'!$E:$E,Summary!$D$1) -> 0 | H25: =COUNTIFS('2e. Reporting'!$I:$I,Summary!$A25,'2e. Reporting'!$C:$C,Summary!H$19,'2e. Reporting'!$E:$E,Summary!$D$1) -> 8 | I25: =C25+F25 -> 66 | J25: =D25+G25 -> 0 | K25: =H25+E25 -> 8 | L25: =COUNTIFS('2e. Reporting'!$I:$I,Summary!$A25,'2e. Reporting'!$J:$J,Summary!L$19,'2e. Reporting'!$E:$E,Summary!$C$1) -> 49 | M25: =COUNTIFS('2e. Reporting'!$I:$I,Summary!$A25,'2e. Reporting'!$J:$J,Summary!M$19,'2e. Reporting'!$E:$E,Summary!$C$1) -> 0 | N25: =COUNTIFS('2e. Reporting'!$I:$I,Summary!$A25,'2e. Reporting'!$J:$J,Summary!N$19,'2e. Reporting'!$E:$E,Summary!$C$1) -> 0 | O25: =COUNTIFS('2e. Reporting'!$I:$I,Summary!$A25,'2e. Reporting'!$J:$J,Summary!O$19,'2e. Reporting'!$E:$E,Summary!$D$1) -> 19 | P25: =COUNTIFS('2e. Reporting'!$I:$I,Summary!$A25,'2e. Reporting'!$J:$J,Summary!P$19,'2e. Reporting'!$E:$E,Summary!$D$1) -> 0 | Q25: =COUNTIFS('2e. Reporting'!$I:$I,Summary!$A25,'2e. Reporting'!$J:$J,Summary!Q$19,'2e. Reporting'!$E:$E,Summary!$D$1) -> 0 | R25: =L25+O25 -> 68 | S25: =M25+P25 -> 0 | T25: =Q25+N25 -> 0 | U25: =R25-I25 -> 2 | V25: =S25-J25 -> 0 | W25: =T25-K25 -> -8
A27: 3a | B27: Security | C27: =COUNTIFS('3a. Security'!$I:$I,Summary!$A27,'3a. Security'!$C:$C,Summary!C$19,'3a. Security'!$E:$E,Summary!$C$1) -> 6 | D27: =COUNTIFS('3a. Security'!$I:$I,Summary!$A27,'3a. Security'!$C:$C,Summary!D$19,'3a. Security'!$E:$E,Summary!$C$1) -> 0 | E27: =COUNTIFS('3a. Security'!$I:$I,Summary!$A27,'3a. Security'!$C:$C,Summary!E$19,'3a. Security'!$E:$E,Summary!$C$1) -> 0 | F27: =COUNTIFS('3a. Security'!$I:$I,Summary!$A27,'3a. Security'!$C:$C,Summary!F$19,'3a. Security'!$E:$E,Summary!$D$1) -> 0 | G27: =COUNTIFS('3a. Security'!$I:$I,Summary!$A27,'3a. Security'!$C:$C,Summary!G$19,'3a. Security'!$E:$E,Summary!$D$1) -> 0 | H27: =COUNTIFS('3a. Security'!$I:$I,Summary!$A27,'3a. Security'!$C:$C,Summary!H$19,'3a. Security'!$E:$E,Summary!$D$1) -> 0 | I27: =C27+F27 -> 6 | J27: =D27+G27 -> 0 | K27: =H27+E27 -> 0 | L27: =COUNTIFS('3a. Security'!$I:$I,Summary!$A27,'3a. Security'!$J:$J,Summary!L$19,'3a. Security'!$E:$E,Summary!$C$1) -> 6 | M27: =COUNTIFS('3a. Security'!$I:$I,Summary!$A27,'3a. Security'!$J:$J,Summary!M$19,'3a. Security'!$E:$E,Summary!$C$1) -> 0 | N27: =COUNTIFS('3a. Security'!$I:$I,Summary!$A27,'3a. Security'!$J:$J,Summary!N$19,'3a. Security'!$E:$E,Summary!$C$1) -> 0 | O27: =COUNTIFS('3a. Security'!$I:$I,Summary!$A27,'3a. Security'!$J:$J,Summary!O$19,'3a. Security'!$E:$E,Summary!$D$1) -> 0 | P27: =COUNTIFS('3a. Security'!$I:$I,Summary!$A27,'3a. Security'!$J:$J,Summary!P$19,'3a. Security'!$E:$E,Summary!$D$1) -> 0 | Q27: =COUNTIFS('3a. Security'!$I:$I,Summary!$A27,'3a. Security'!$J:$J,Summary!Q$19,'3a. Security'!$E:$E,Summary!$D$1) -> 0 | R27: =L27+O27 -> 6 | S27: =M27+P27 -> 0 | T27: =Q27+N27 -> 0 | U27: =R27-I27 -> 0 | V27: =S27-J27 -> 0 | W27: =T27-K27 -> 0
A28: 3b | B28: User Interface & User Exp | C28: =COUNTIFS('3b. User Interface and User Exp'!$I:$I,Summary!$A28,'3b. User Interface and User Exp'!$C:$C,Summary!C$19,'3b. User Interface and User Exp'!$E:$E,Summary!$C$1) -> 2 | D28: =COUNTIFS('3b. User Interface and User Exp'!$I:$I,Summary!$A28,'3b. User Interface and User Exp'!$C:$C,Summary!D$19,'3b. User Interface and User Exp'!$E:$E,Summary!$C$1) -> 0 | E28: =COUNTIFS('3b. User Interface and User Exp'!$I:$I,Summary!$A28,'3b. User Interface and User Exp'!$C:$C,Summary!E$19,'3b. User Interface and User Exp'!$E:$E,Summary!$C$1) -> 0 | F28: =COUNTIFS('3b. User Interface and User Exp'!$I:$I,Summary!$A28,'3b. User Interface and User Exp'!$C:$C,Summary!F$19,'3b. User Interface and User Exp'!$E:$E,Summary!$D$1) -> 5 | G28: =COUNTIFS('3b. User Interface and User Exp'!$I:$I,Summary!$A28,'3b. User Interface and User Exp'!$C:$C,Summary!G$19,'3b. User Interface and User Exp'!$E:$E,Summary!$D$1) -> 0 | H28: =COUNTIFS('3b. User Interface and User Exp'!$I:$I,Summary!$A28,'3b. User Interface and User Exp'!$C:$C,Summary!H$19,'3b. User Interface and User Exp'!$E:$E,Summary!$D$1) -> 0 | I28: =C28+F28 -> 7 | J28: =D28+G28 -> 0 | K28: =H28+E28 -> 0 | L28: =COUNTIFS('3b. User Interface and User Exp'!$I:$I,Summary!$A28,'3b. User Interface and User Exp'!$J:$J,Summary!L$19,'3b. User Interface and User Exp'!$E:$E,Summary!$C$1) -> 2 | M28: =COUNTIFS('3b. User Interface and User Exp'!$I:$I,Summary!$A28,'3b. User Interface and User Exp'!$J:$J,Summary!M$19,'3b. User Interface and User Exp'!$E:$E,Summary!$C$1) -> 0 | N28: =COUNTIFS('3b. User Interface and User Exp'!$I:$I,Summary!$A28,'3b. User Interface and User Exp'!$J:$J,Summary!N$19,'3b. User Interface and User Exp'!$E:$E,Summary!$C$1) -> 0 | O28: =COUNTIFS('3b. User Interface and User Exp'!$I:$I,Summary!$A28,'3b. User Interface and User Exp'!$J:$J,Summary!O$19,'3b. User Interface and User Exp'!$E:$E,Summary!$D$1) -> 5 | P28: =COUNTIFS('3b. User Interface and User Exp'!$I:$I,Summary!$A28,'3b. User Interface and User Exp'!$J:$J,Summary!P$19,'3b. User Interface and User Exp'!$E:$E,Summary!$D$1) -> 0 | Q28: =COUNTIFS('3b. User Interface and User Exp'!$I:$I,Summary!$A28,'3b. User Interface and User Exp'!$J:$J,Summary!Q$19,'3b. User Interface and User Exp'!$E:$E,Summary!$D$1) -> 0 | R28: =L28+O28 -> 7 | S28: =M28+P28 -> 0 | T28: =Q28+N28 -> 0 | U28: =R28-I28 -> 0 | V28: =S28-J28 -> 0 | W28: =T28-K28 -> 0
A29: 3c | B29: Performance & Scalability | C29: =COUNTIFS('3c. Performance-Scalability'!$I:$I,Summary!$A29,'3c. Performance-Scalability'!$C:$C,Summary!C$19,'3c. Performance-Scalability'!$E:$E,Summary!$C$1) -> 0 | D29: =COUNTIFS('3c. Performance-Scalability'!$I:$I,Summary!$A29,'3c. Performance-Scalability'!$C:$C,Summary!D$19,'3c. Performance-Scalability'!$E:$E,Summary!$C$1) -> 0 | E29: =COUNTIFS('3c. Performance-Scalability'!$I:$I,Summary!$A29,'3c. Performance-Scalability'!$C:$C,Summary!E$19,'3c. Performance-Scalability'!$E:$E,Summary!$C$1) -> 0 | F29: =COUNTIFS('3c. Performance-Scalability'!$I:$I,Summary!$A29,'3c. Performance-Scalability'!$C:$C,Summary!F$19,'3c. Performance-Scalability'!$E:$E,Summary!$D$1) -> 6 | G29: =COUNTIFS('3c. Performance-Scalability'!$I:$I,Summary!$A29,'3c. Performance-Scalability'!$C:$C,Summary!G$19,'3c. Performance-Scalability'!$E:$E,Summary!$D$1) -> 0 | H29: =COUNTIFS('3c. Performance-Scalability'!$I:$I,Summary!$A29,'3c. Performance-Scalability'!$C:$C,Summary!H$19,'3c. Performance-Scalability'!$E:$E,Summary!$D$1) -> 0 | I29: =C29+F29 -> 6 | J29: =D29+G29 -> 0 | K29: =H29+E29 -> 0 | L29: =COUNTIFS('3c. Performance-Scalability'!$I:$I,Summary!$A29,'3c. Performance-Scalability'!$J:$J,Summary!L$19,'3c. Performance-Scalability'!$E:$E,Summary!$C$1) -> 0 | M29: =COUNTIFS('3c. Performance-Scalability'!$I:$I,Summary!$A29,'3c. Performance-Scalability'!$J:$J,Summary!M$19,'3c. Performance-Scalability'!$E:$E,Summary!$C$1) -> 0 | N29: =COUNTIFS('3c. Performance-Scalability'!$I:$I,Summary!$A29,'3c. Performance-Scalability'!$J:$J,Summary!N$19,'3c. Performance-Scalability'!$E:$E,Summary!$C$1) -> 0 | O29: =COUNTIFS('3c. Performance-Scalability'!$I:$I,Summary!$A29,'3c. Performance-Scalability'!$J:$J,Summary!O$19,'3c. Performance-Scalability'!$E:$E,Summary!$D$1) -> 6 | P29: =COUNTIFS('3c. Performance-Scalability'!$I:$I,Summary!$A29,'3c. Performance-Scalability'!$J:$J,Summary!P$19,'3c. Performance-Scalability'!$E:$E,Summary!$D$1) -> 0 | Q29: =COUNTIFS('3c. Performance-Scalability'!$I:$I,Summary!$A29,'3c. Performance-Scalability'!$J:$J,Summary!Q$19,'3c. Performance-Scalability'!$E:$E,Summary!$D$1) -> 0 | R29: =L29+O29 -> 6 | S29: =M29+P29 -> 0 | T29: =Q29+N29 -> 0 | U29: =R29-I29 -> 0 | V29: =S29-J29 -> 0 | W29: =T29-K29 -> 0
A30: 3d | B30: Support-Maintenance | C30: =COUNTIFS('3d. Support-Maintenance'!$I:$I,Summary!$A30,'3d. Support-Maintenance'!$C:$C,Summary!C$19,'3d. Support-Maintenance'!$E:$E,Summary!$C$1) -> 5 | D30: =COUNTIFS('3d. Support-Maintenance'!$I:$I,Summary!$A30,'3d. Support-Maintenance'!$C:$C,Summary!D$19,'3d. Support-Maintenance'!$E:$E,Summary!$C$1) -> 0 | E30: =COUNTIFS('3d. Support-Maintenance'!$I:$I,Summary!$A30,'3d. Support-Maintenance'!$C:$C,Summary!E$19,'3d. Support-Maintenance'!$E:$E,Summary!$C$1) -> 0 | F30: =COUNTIFS('3d. Support-Maintenance'!$I:$I,Summary!$A30,'3d. Support-Maintenance'!$C:$C,Summary!F$19,'3d. Support-Maintenance'!$E:$E,Summary!$D$1) -> 2 | G30: =COUNTIFS('3d. Support-Maintenance'!$I:$I,Summary!$A30,'3d. Support-Maintenance'!$C:$C,Summary!G$19,'3d. Support-Maintenance'!$E:$E,Summary!$D$1) -> 0 | H30: =COUNTIFS('3d. Support-Maintenance'!$I:$I,Summary!$A30,'3d. Support-Maintenance'!$C:$C,Summary!H$19,'3d. Support-Maintenance'!$E:$E,Summary!$D$1) -> 0 | I30: =C30+F30 -> 7 | J30: =D30+G30 -> 0 | K30: =H30+E30 -> 0 | L30: =COUNTIFS('3d. Support-Maintenance'!$I:$I,Summary!$A30,'3d. Support-Maintenance'!$J:$J,Summary!L$19,'3d. Support-Maintenance'!$E:$E,Summary!$C$1) -> 5 | M30: =COUNTIFS('3d. Support-Maintenance'!$I:$I,Summary!$A30,'3d. Support-Maintenance'!$J:$J,Summary!M$19,'3d. Support-Maintenance'!$E:$E,Summary!$C$1) -> 0 | N30: =COUNTIFS('3d. Support-Maintenance'!$I:$I,Summary!$A30,'3d. Support-Maintenance'!$J:$J,Summary!N$19,'3d. Support-Maintenance'!$E:$E,Summary!$C$1) -> 0 | O30: =COUNTIFS('3d. Support-Maintenance'!$I:$I,Summary!$A30,'3d. Support-Maintenance'!$J:$J,Summary!O$19,'3d. Support-Maintenance'!$E:$E,Summary!$D$1) -> 2 | P30: =COUNTIFS('3d. Support-Maintenance'!$I:$I,Summary!$A30,'3d. Support-Maintenance'!$J:$J,Summary!P$19,'3d. Support-Maintenance'!$E:$E,Summary!$D$1) -> 0 | Q30: =COUNTIFS('3d. Support-Maintenance'!$I:$I,Summary!$A30,'3d. Support-Maintenance'!$J:$J,Summary!Q$19,'3d. Support-Maintenance'!$E:$E,Summary!$D$1) -> 0 | R30: =L30+O30 -> 7 | S30: =M30+P30 -> 0 | T30: =Q30+N30 -> 0 | U30: =R30-I30 -> 0 | V30: =S30-J30 -> 0 | W30: =T30-K30 -> 0
A31: 3e | B31: Reliability-Availability | C31: =COUNTIFS('3e. Reliability-Availability'!$I:$I,Summary!$A31,'3e. Reliability-Availability'!$C:$C,Summary!C$19,'3e. Reliability-Availability'!$E:$E,Summary!$C$1) -> 4 | D31: =COUNTIFS('3e. Reliability-Availability'!$I:$I,Summary!$A31,'3e. Reliability-Availability'!$C:$C,Summary!D$19,'3e. Reliability-Availability'!$E:$E,Summary!$C$1) -> 0 | E31: =COUNTIFS('3e. Reliability-Availability'!$I:$I,Summary!$A31,'3e. Reliability-Availability'!$C:$C,Summary!E$19,'3e. Reliability-Availability'!$E:$E,Summary!$C$1) -> 0 | F31: =COUNTIFS('3e. Reliability-Availability'!$I:$I,Summary!$A31,'3e. Reliability-Availability'!$C:$C,Summary!F$19,'3e. Reliability-Availability'!$E:$E,Summary!$D$1) -> 4 | G31: =COUNTIFS('3e. Reliability-Availability'!$I:$I,Summary!$A31,'3e. Reliability-Availability'!$C:$C,Summary!G$19,'3e. Reliability-Availability'!$E:$E,Summary!$D$1) -> 0 | H31: =COUNTIFS('3e. Reliability-Availability'!$I:$I,Summary!$A31,'3e. Reliability-Availability'!$C:$C,Summary!H$19,'3e. Reliability-Availability'!$E:$E,Summary!$D$1) -> 0 | I31: =C31+F31 -> 8 | J31: =D31+G31 -> 0 | K31: =H31+E31 -> 0 | L31: =COUNTIFS('3e. Reliability-Availability'!$I:$I,Summary!$A31,'3e. Reliability-Availability'!$J:$J,Summary!L$19,'3e. Reliability-Availability'!$E:$E,Summary!$C$1) -> 4 | M31: =COUNTIFS('3e. Reliability-Availability'!$I:$I,Summary!$A31,'3e. Reliability-Availability'!$J:$J,Summary!M$19,'3e. Reliability-Availability'!$E:$E,Summary!$C$1) -> 0 | N31: =COUNTIFS('3e. Reliability-Availability'!$I:$I,Summary!$A31,'3e. Reliability-Availability'!$J:$J,Summary!N$19,'3e. Reliability-Availability'!$E:$E,Summary!$C$1) -> 0 | O31: =COUNTIFS('3e. Reliability-Availability'!$I:$I,Summary!$A31,'3e. Reliability-Availability'!$J:$J,Summary!O$19,'3e. Reliability-Availability'!$E:$E,Summary!$D$1) -> 4 | P31: =COUNTIFS('3e. Reliability-Availability'!$I:$I,Summary!$A31,'3e. Reliability-Availability'!$J:$J,Summary!P$19,'3e. Reliability-Availability'!$E:$E,Summary!$D$1) -> 0 | Q31: =COUNTIFS('3e. Reliability-Availability'!$I:$I,Summary!$A31,'3e. Reliability-Availability'!$J:$J,Summary!Q$19,'3e. Reliability-Availability'!$E:$E,Summary!$D$1) -> 0 | R31: =L31+O31 -> 8 | S31: =M31+P31 -> 0 | T31: =Q31+N31 -> 0 | U31: =R31-I31 -> 0 | V31: =S31-J31 -> 0 | W31: =T31-K31 -> 0
A32: 3f | B32: Integration | C32: =COUNTIFS('3f. Integration'!$I:$I,Summary!$A32,'3f. Integration'!$C:$C,Summary!C$19,'3f. Integration'!$E:$E,Summary!$C$1) -> 12 | D32: =COUNTIFS('3f. Integration'!$I:$I,Summary!$A32,'3f. Integration'!$C:$C,Summary!D$19,'3f. Integration'!$E:$E,Summary!$C$1) -> 0 | E32: =COUNTIFS('3f. Integration'!$I:$I,Summary!$A32,'3f. Integration'!$C:$C,Summary!E$19,'3f. Integration'!$E:$E,Summary!$C$1) -> 0 | F32: =COUNTIFS('3f. Integration'!$I:$I,Summary!$A32,'3f. Integration'!$C:$C,Summary!F$19,'3f. Integration'!$E:$E,Summary!$D$1) -> 4 | G32: =COUNTIFS('3f. Integration'!$I:$I,Summary!$A32,'3f. Integration'!$C:$C,Summary!G$19,'3f. Integration'!$E:$E,Summary!$D$1) -> 0 | H32: =COUNTIFS('3f. Integration'!$I:$I,Summary!$A32,'3f. Integration'!$C:$C,Summary!H$19,'3f. Integration'!$E:$E,Summary!$D$1) -> 1 | I32: =C32+F32 -> 16 | J32: =D32+G32 -> 0 | K32: =H32+E32 -> 1 | L32: =COUNTIFS('3f. Integration'!$I:$I,Summary!$A32,'3f. Integration'!$J:$J,Summary!L$19,'3f. Integration'!$E:$E,Summary!$C$1) -> 12 | M32: =COUNTIFS('3f. Integration'!$I:$I,Summary!$A32,'3f. Integration'!$J:$J,Summary!M$19,'3f. Integration'!$E:$E,Summary!$C$1) -> 0 | N32: =COUNTIFS('3f. Integration'!$I:$I,Summary!$A32,'3f. Integration'!$J:$J,Summary!N$19,'3f. Integration'!$E:$E,Summary!$C$1) -> 0 | O32: =COUNTIFS('3f. Integration'!$I:$I,Summary!$A32,'3f. Integration'!$J:$J,Summary!O$19,'3f. Integration'!$E:$E,Summary!$D$1) -> 4 | P32: =COUNTIFS('3f. Integration'!$I:$I,Summary!$A32,'3f. Integration'!$J:$J,Summary!P$19,'3f. Integration'!$E:$E,Summary!$D$1) -> 0 | Q32: =COUNTIFS('3f. Integration'!$I:$I,Summary!$A32,'3f. Integration'!$J:$J,Summary!Q$19,'3f. Integration'!$E:$E,Summary!$D$1) -> 0 | R32: =L32+O32 -> 16 | S32: =M32+P32 -> 0 | T32: =Q32+N32 -> 0 | U32: =R32-I32 -> 0 | V32: =S32-J32 -> 0 | W32: =T32-K32 -> -1
A33: 3g | B33: Configurability | C33: =COUNTIFS('3g. Configurability'!$I:$I,Summary!$A33,'3g. Configurability'!$C:$C,Summary!C$19,'3g. Configurability'!$E:$E,Summary!$C$1) -> 3 | D33: =COUNTIFS('3g. Configurability'!$I:$I,Summary!$A33,'3g. Configurability'!$C:$C,Summary!D$19,'3g. Configurability'!$E:$E,Summary!$C$1) -> 0 | E33: =COUNTIFS('3g. Configurability'!$I:$I,Summary!$A33,'3g. Configurability'!$C:$C,Summary!E$19,'3g. Configurability'!$E:$E,Summary!$C$1) -> 0 | F33: =COUNTIFS('3g. Configurability'!$I:$I,Summary!$A33,'3g. Configurability'!$C:$C,Summary!F$19,'3g. Configurability'!$E:$E,Summary!$D$1) -> 1 | G33: =COUNTIFS('3g. Configurability'!$I:$I,Summary!$A33,'3g. Configurability'!$C:$C,Summary!G$19,'3g. Configurability'!$E:$E,Summary!$D$1) -> 0 | H33: =COUNTIFS('3g. Configurability'!$I:$I,Summary!$A33,'3g. Configurability'!$C:$C,Summary!H$19,'3g. Configurability'!$E:$E,Summary!$D$1) -> 0 | I33: =C33+F33 -> 4 | J33: =D33+G33 -> 0 | K33: =H33+E33 -> 0 | L33: =COUNTIFS('3g. Configurability'!$I:$I,Summary!$A33,'3g. Configurability'!$J:$J,Summary!L$19,'3g. Configurability'!$E:$E,Summary!$C$1) -> 3 | M33: =COUNTIFS('3g. Configurability'!$I:$I,Summary!$A33,'3g. Configurability'!$J:$J,Summary!M$19,'3g. Configurability'!$E:$E,Summary!$C$1) -> 0 | N33: =COUNTIFS('3g. Configurability'!$I:$I,Summary!$A33,'3g. Configurability'!$J:$J,Summary!N$19,'3g. Configurability'!$E:$E,Summary!$C$1) -> 0 | O33: =COUNTIFS('3g. Configurability'!$I:$I,Summary!$A33,'3g. Configurability'!$J:$J,Summary!O$19,'3g. Configurability'!$E:$E,Summary!$D$1) -> 1 | P33: =COUNTIFS('3g. Configurability'!$I:$I,Summary!$A33,'3g. Configurability'!$J:$J,Summary!P$19,'3g. Configurability'!$E:$E,Summary!$D$1) -> 0 | Q33: =COUNTIFS('3g. Configurability'!$I:$I,Summary!$A33,'3g. Configurability'!$J:$J,Summary!Q$19,'3g. Configurability'!$E:$E,Summary!$D$1) -> 0 | R33: =L33+O33 -> 4 | S33: =M33+P33 -> 0 | T33: =Q33+N33 -> 0 | U33: =R33-I33 -> 0 | V33: =S33-J33 -> 0 | W33: =T33-K33 -> 0
A34: 3h | B34: Compliance | C34: =COUNTIFS('3h. Compliance'!$I:$I,Summary!$A34,'3h. Compliance'!$C:$C,Summary!C$19,'3h. Compliance'!$E:$E,Summary!$C$1) -> 4 | D34: =COUNTIFS('3h. Compliance'!$I:$I,Summary!$A34,'3h. Compliance'!$C:$C,Summary!D$19,'3h. Compliance'!$E:$E,Summary!$C$1) -> 0 | E34: =COUNTIFS('3h. Compliance'!$I:$I,Summary!$A34,'3h. Compliance'!$C:$C,Summary!E$19,'3h. Compliance'!$E:$E,Summary!$C$1) -> 0 | F34: =COUNTIFS('3h. Compliance'!$I:$I,Summary!$A34,'3h. Compliance'!$C:$C,Summary!F$19,'3h. Compliance'!$E:$E,Summary!$D$1) -> 3 | G34: =COUNTIFS('3h. Compliance'!$I:$I,Summary!$A34,'3h. Compliance'!$C:$C,Summary!G$19,'3h. Compliance'!$E:$E,Summary!$D$1) -> 0 | H34: =COUNTIFS('3h. Compliance'!$I:$I,Summary!$A34,'3h. Compliance'!$C:$C,Summary!H$19,'3h. Compliance'!$E:$E,Summary!$D$1) -> 0 | I34: =C34+F34 -> 7 | J34: =D34+G34 -> 0 | K34: =H34+E34 -> 0 | L34: =COUNTIFS('3h. Compliance'!$I:$I,Summary!$A34,'3h. Compliance'!$J:$J,Summary!L$19,'3h. Compliance'!$E:$E,Summary!$C$1) -> 4 | M34: =COUNTIFS('3h. Compliance'!$I:$I,Summary!$A34,'3h. Compliance'!$J:$J,Summary!M$19,'3h. Compliance'!$E:$E,Summary!$C$1) -> 0 | N34: =COUNTIFS('3h. Compliance'!$I:$I,Summary!$A34,'3h. Compliance'!$J:$J,Summary!N$19,'3h. Compliance'!$E:$E,Summary!$C$1) -> 0 | O34: =COUNTIFS('3h. Compliance'!$I:$I,Summary!$A34,'3h. Compliance'!$J:$J,Summary!O$19,'3h. Compliance'!$E:$E,Summary!$D$1) -> 3 | P34: =COUNTIFS('3h. Compliance'!$I:$I,Summary!$A34,'3h. Compliance'!$J:$J,Summary!P$19,'3h. Compliance'!$E:$E,Summary!$D$1) -> 0 | Q34: =COUNTIFS('3h. Compliance'!$I:$I,Summary!$A34,'3h. Compliance'!$J:$J,Summary!Q$19,'3h. Compliance'!$E:$E,Summary!$D$1) -> 0 | R34: =L34+O34 -> 7 | S34: =M34+P34 -> 0 | T34: =Q34+N34 -> 0 | U34: =R34-I34 -> 0 | V34: =S34-J34 -> 0 | W34: =T34-K34 -> 0
B35: Total | C35: =SUM(C21:C25,C27:C34) -> 352 | D35: =SUM(D21:D25,D27:D34) -> 0 | E35: =SUM(E21:E25,E27:E34) -> 0 | F35: =SUM(F21:F25,F27:F34) -> 172 | G35: =SUM(G21:G25,G27:G34) -> 4 | H35: =SUM(H21:H25,H27:H34) -> 78 | I35: =SUM(I21:I25,I27:I34) -> 524 | J35: =SUM(J21:J25,J27:J34) -> 4 | ... W35: =SUM(W21:W25,W27:W34) -> -74

Sheet 2a. Administration
A1: 2a. | B1: Administration. In terms of managing business-level configurations and rules, the Software shall: | C1: Fulfil Certis' Requirements? (Yes/No/Partial) | D1: Remarks | E1: SG (X if required SX Showstopper) | F1: AU (X if required) | G1: Revised Requirements | H1: Certis Remarks | I1: Indicator | J1: Response (Yes/No/Partial) | K1: Remarks | L1: Cadence Related
A2: i. | B2: Role-Based Access Control
B3: Allow the System Administrator to define and manage user roles, each with specific permissions and access rights. Access levels should be aligned with job responsibilities to enforce the principle of least privilege. | C3: Y | E3: SX | F3: X | G3: SX | I3: 2a | J3: Y | L3: n | O3: BU Admin x 1 CLS/CAS/SLS Admin x 2 Segment Head x 5 Demand Mgr x 5 Divison Mgr x 25 OC x -- Cluster Exec x -- Site Supervisor x -- Officer x -- CICC Demand Mgr CICC Duty OM CICC Ops Planner CICC Time Admin Line HR QMT Deployment Mgr Deployment Exec
A4: ii. | B4: Data-level Access Control
B5: Allow the system administrator to assign granular permissions, with users having access (i.e. a combination of CRUD rights) to only specific records/groups of records within the Software Eg, two users having access to same screen might have a different level of Authorization based on role, data and action to perform on the screen | C5: Y | E5: SX | F5: X | G5: SX | I5: 2a | J5: Y | K5: Part of custom RBAC | L5: Y
A6: iii. | B6: Segregation of Duties (SOD)
B7: 1. Include functionality to identify and report potential role conflicts within the access control structure. This helps prevent situations where a single user may have conflicting or incompatible duties. For example, employees given access rights to update rosters shall not be able to update a roster which he/she is assigned to. | C7: Y | E7: SX | F7: X | G7: SX | I7: 2a | J7: Y | K7: Part of custom RBAC | L7: Y
B8: 2. Functionality shall extend to workflows and business processes. The Software should allow administrators to define and enforce the separation of critical tasks to prevent unauthorized or conflicting actions. | C8: Y | E8: SX | F8: X | G8: SX | I8: 2a | J8: Y | K8: These would need to be specified and can be built dynamically or if more static may be directly incorporated. | L8: Y
B9: 3. Pre-built and configurable workflows to enable notification and approval processes across SOD layers, shall be included. | C9: Y | D9: Approval workflows are pre-built into the system based on hierarchy and/or direct supervisor. | E9: SX | F9: X | G9: SX | I9: 2a | J9: Y | K9: Same as above. | L9: Y
A10: iv. | B10: Access Monitoring and Logging
B11: User Activity Logging - Log user activities, including login attempts, access to sensitive data, and changes to configuration settings. Detailed logs should be maintained to track user actions for auditing and forensic purposes. | C11: Y | E11: SX | F11: X | G11: SX | I11: 2a | J11: Y | L11: n
B12: Real-time Monitoring and Alerts - Implement real-time monitoring capabilities to detect and alert administrators about suspicious or unauthorized activities. Automated alerts should be triggered based on predefined thresholds and patterns indicative of security risks. | C12: Y | E12: SX | F12: X | G12: SX | I12: 2a | J12: Y | L12: Y
B13: Audit trails - The software must provide comprehensive audit trails that capture all relevant access control activities and changes. These audit trails should be easily accessible via a self-service user interface within the Software for internal and external audits to demonstrate compliance. | C13: Y | E13: SX | F13: X | G13: SX | I13: 2a | J13: Y | L13: n
A14: v. | B14: Automatic Archival of users
B15: Have the capability to automatically archive data as “housekeeping” to maintain only active data in the system. This shall be governed by rules e.g. User has not been rostered for 30 days or User has not performed a shift in 30 days, e.g. Rosters are archived after 12months post-execution, but retained for a minimum of 7 years. | C15: Y | D15: Currently data is retained for 7 years. Rules around "housekeeping" and "rules" would necessitate extension of the existing functionality. | E15: SX | F15: X | G15: SX | I15: 2a | J15: Y | L15: n
A16: vi. | B16: Contract Creation/Import
B17: The solution must support the automated creation or import of master data from SAP S/4HANA. | C17: Y | E17: SX | F17: X | G17: SX | I17: 2a | J17: Y | L17: n
A18: vii. | B18: Types of work/demand items – include the following work/demand item types
B19: The solution must allow configurable categorisation of work or demand items to align with operational needs such as deployable, billable, and user-defined demand types Also the same information must be available in reports | C19: Y | D19: These can be labelled with tags or CG/CSG. | E19: SX | F19: X | G19: X | H19: Requires Demand Object | I19: 2a | J19: Y | L19: n
A20: viii. | B20: Employee Attributes
B21: The solution must support configurable employee attributes to enable accurate rostering, role assignment, and compliance tracking. | C21: Y | E21: SX | F21: X | G21: X | I21: 2a | J21: Y | L21: n
A22: ix. | B22: Compliance Functions
B23: The solution must support the application of relevant industrial awards, enterprise agreements, and employment policies to ensure compliance with applicable wage, hour, and employment regulations. | C23: Y | E23: SX | F23: X | G23: SX | I23: 2a | J23: Y | L23: n
A24: x. | B24: Leave and Accrual Tracking Functions
B25: The solution must provide configurable leave and accrual management capabilities that support compliance with local regulations, company policies, and relevant industrial awards. It should enable the application of varying leave rules, entitlements, and approval workflows across different employee types, business units, and operating jurisdictions | C25: Y | D25: This is handled by SAP and then the banks and values are pushed to WorkAxle. WorkAxle also has local time banks for WFM based accruals and tracking that need to be captured in addition to the standard HR banks. | E25: X | F25: X | G25: X | I25: 2a | J25: Y | K25: This is handled by SAP and then the banks and values are pushed to WorkAxle. WorkAxle also has local time banks for WFM based accruals and tracking that need to be captured in addition to the standard HR banks. | L25: n
A26: xi. | B26: Payroll Calculation Capabilities
B27: The solution must support accurate and automated interpretation of timesheet data in line with applicable industrial awards, enterprise agreements, and company policies. It must be capable of applying complex working conditions such as overtime, shift differentials, and allowances, and provide flexibility to accommodate different rules by employee type, business unit, and union agreements. The interpreted data must integrate seamlessly with SAP SuccessFactors Employee Central Payroll for processing. | C27: Y | E27: SX | F27: X | G27: SX | H27: Handled by SF | I27: 2a | J27: Y | L27: n
A28: xii. | B28: Other Payroll Calculation Capabilities
B29: The solution must support automated triggering of allowances based on configurable conditions. These triggers may be based on, but are not limited to, criteria such as site, task, position, or individual employee level. Triggers should also be configurable based on the number of days or hours worked, and after crossing specific thresholds—such as exceeding certain working hours—with the ability to define minimum and maximum allowance limits per day, week, or defined period. | C29: Y | D29: Would need complete list of detailed requirements for this but we have a detailed rule engine that can handle many complex situations and is the most flexible and modern rule engine on the market for enterprise level WFM. | E29: SX | F29: X | G29: SX | H29: Manual Tag Paycode is allowed. Pay rules to incentives & Allowances | I29: 2a | J29: Y | L29: n
A30: xiii. | B30: Basic employee award interpretation – have the capability to interpret and calculate Employee Agreement terms of: | F30: Recommend deleting and providing the copies of the relevant awards and enterprise agreements.
B31: 1) Overtime each day stands alone | C31: Y | E31: SX | G31: N | H31: Not Required | I31: 2a | L31: n
B32: 2) Automatic Meal Allowance on 2nd Allowance (EBA) after 5hrs work | C32: Y | E32: X | G32: N | H32: Not Required | I32: 2a | L32: n
B33: 3) Short Shift Allowance (EBA) | C33: Y | E33: SX | G33: N | H33: Not Required | I33: 2a | L33: n
B34: 4) Broken Shift Allowance (EBA) | C34: Y | E34: SX | G34: N | H34: Not Required | I34: 2a | L34: n
B35: 5) Day Loading (conditional on start on or before 5.30am start of on or after 18.30 finish) | C35: Y | E35: X | G35: N | H35: Not Required | I35: 2a | L35: n
B36: 6) PHNW payable on off Days for 7-day workers (EBA and award) | C36: Y | E36: X | G36: N | H36: Not Required | I36: 2a | L36: n
B37: 7) Leave Loading automatic calculation payable on either 17.5% of higher loading that would have been earned if working | C37: P | D37: Need more specific information | E37: X | G37: N | H37: Not Required | I37: 2a | L37: n
B38: 8) Ability to distinguish when Rotating or Permanent Night Loading is payable, when 2/3 of ordinary shifts start between 00:00 and 06:00 then Permanent night loading is payable. | C38: Y | E38: X | G38: N | H38: Not Required | I38: 2a | L38: n
B39: 9)Ability to seamlessly integrate payroll and relate information such as industry award and what level to pay personnel. | C39: Y | E39: SX | G39: N | H39: Not Required | I39: 2a | L39: n
B40: 10) Has the demonstrated capability to interpret all aspects of the Security Services Industry Award [MA000016] | C40: P | D40: Has demonstratably handled similar complexity awards within AU but never specifically the Security Services Industry Award. | E40: X | G40: N | H40: Not Required | I40: 2a | L40: n
...

Sheet 2b. Planning
A1: 2b. | B1: Planning. In terms of functionalities in the roster design and forecasting, the Software shall: | C1: Fulfil Certis' Requirements? (Yes/No/Partial) | D1: Remarks | E1: SG (X if required SX Showstopper) | F1: AU (X if required) | G1: Revised Requirements | H1: Certis Remarks | I1: Indicator | J1: Response (Yes/No/Partial) | K1: Remarks | L1: Cadence Related
A2: i. | B2: Roster Forecasting.
B3: The solution must able to generate roster patterns that optimise cost-efficiency while ensuring full compliance with applicable industrial instruments | C3: Y | D3: More specific information is necessary. High likelyhood that a tailored model along with tailored integration for input parameters is needed. | E3: SX | F3: X | G3: SX | H3: No need Cost efficiency. Regulatory Requirement is a must | I3: 2b | J3: Y | K3: Can do roster creation and validate that all rosters are compliant. Any non-compliance will be flagged by the system and can be handled by the planners. | L3: n
B4: The solution must dynamically adjust workforce schedules based on forecasted demand (i.e. passenger throughput at a screening point). The system must ensure compliance with all relevant labor regulations and support the creation of cost-effective, efficient rosters that maintain high service standards during varying demand periods. | C4: Y | D4: More specific information is necessary. High likelyhood that a tailored model along with tailored integration for input parameters is needed. | E4: SX | F4: X | G4: X | H4: Regulatory Requirement is a must | I4: 2b | J4: Y | K4: Same as above | L4: n
B5: The solution must enable forecasting of workforce coverage by assessing resource availability for future dates. This should include consideration of approved leave, projected headcount, and historical absenteeism trends to ensure adequate staffing and operational continuity. | C5: Y | D5: More specific information is necessary. High likelyhood that a tailored model along with tailored integration for input parameters is needed. | E5: SX | F5: X | G5: X | H5: Regulatory Requirement is a must | I5: 2b | J5: Y | K5: Same as above | L5: n
A6: ii. | B6: Standard Roster Types | F6: X
B7: The solution must support the creation and management of configurable roster templates to accommodate a range of operational needs, including rotating shift patterns, demand-driven schedules, standard business weeks, and event- or project-based deployments. | C7: Y | E7: SX | G7: SX | I7: 2b | J7: Y | L7: n
A8: iii. | B8: Special Roster Types | F8: X
B9: Include capability to create unique roster types:
B10: Multi Chain Pattern - Multi Chain Roster Patterns are a specific type of Roster Model that allows employees to switch rosters based on planned demand or workload requirements. This Roster Model is designed to account for fluctuating coverage requirements from week to week. The Multi-Chain Roster is composed of one or more “demand” rosters, that once built allows for employees to switch throughout each roster based on a defined date driven basis. This design allows for:
B11: 1. Efficient control of employee movement between rosters | C11: Y | E11: SX | G11: SX | I11: 2b | J11: Y | L11: n
B12: 2. Automatic activation/de-activation of Roster Patterns based on defined dates | C12: Y | E12: X | G12: X | I12: 2b | J12: Y | L12: n
B13: 3. This allows multiple child/sub rosters to be attached to a single master roster. These rosters can then be date triggered based on varying demand. Personnel inherit the same line number in the roster when switching child rosters. | C13: Y | D13: Need documented process. May require extension. | E13: SX | G13: SX | H13: Split Shift | I13: 2b | J13: Y | L13: n
B14: 4 The solution must support advanced rostering models that enable flexible scheduling in response to variable demand patterns. The system must allow automatic activation or deactivation of roster patterns based on planned operational demand. The solution must enable planners to create optimised rosters that meet operational requirements while minimising labour costs. It should support various workforce types including part-time, casual, resource contractors, and support flexible options such as split shifts. The solution must support rostering across multiple cost centres, allowing resource sharing and optimisation across business units to improve workforce utilisation. | C14: Y | D14: Need documented process. May require extension. | E14: SX | G14: SX | I14: 2b | J14: Y | L14: n
A15: iv. | B15: Cost Minimization through Roster Design
B16: Flexible scheduling – allow Roster Planners various scheduling options including Split Shifts, Part–time work, Resource Contractors, to fill rosters with the lowest cost possible. | C16: P | D16: Need documented process. May require extension. | E16: X | G16: X | H16: Split Shift cost not required | I16: 2b | J16: Y | K16: Split shift no problem, cost optimization adds overhead. As mentioned in the Certis remarks, it is not considered as part of this requirement. That being said, we are currently looking at a way to add cost optimization without affecting performance. | L16: n
A18: v. | B18: Business Workflows
B19: Rule Breaks in Planning – include pre-built and customizable workflows for fatigue and skill rule break handling, with both in-application notifications and email-based notifications for rule break approval processes. | C19: Y | D19: Need documented process. May require extension. | E19: SX | G19: SX | I19: 2b | J19: Y | L19: n
A21: vi. | B21: Special Roster Rules
B22: 1. Fatigue rules
B23: (a) Mandatory rest period between rostered shifts (fatigue rules) – capability to configure a rule of minimum hours of rest between rostered shifts (e.g. 8 hours from end of Shift 1 to start of Shift 2) | C23: Y | E23: SX | G23: SX | I23: 2b | J23: Y | L23: n
B24: (b) Limit maximum working hours per cycle (fatigue rules) . - e.g. no more than 60hrs per week. Special rules apply to employee groups e.g. Students, seasonal. In other words, enforce mandatory rest day within a work period (e.g. 1 rest day per 7 days). | C24: Y | E24: SX | G24: SX | I24: 2b | J24: Y | L24: n
B25: (c) Limit consecutive rostered days (fatigue rules) – capability to configure a rule to limit consecutive rostered days (e.g. maximum of 7 consecutive rostered days) | C25: Y | E25: SX | G25: SX | I25: 2b | J25: Y | L25: n
B26: (d) Limit maximum Overtime (fatigue rules) – capability to l imit the maximum hours of work to 60hrs per week, or an average of multiples of 60hrs based on Roster Cycle, i.e. 120hrs over 2-week cycle, 180hrs over 3-week cycle, 240hrs over 4-week cycle or 480hrs over an 8-week cycle. | C26: Y | E26: SX | G26: SX | I26: 2b | J26: Y | L26: n
B27: (e) Fatigue rules shall be configured to apply to a specific group of personnel (e.g., in Singapore daily max 13 hours for scheme B and 14 hours for scheme A) | C27: Y | E27: SX | G27: SX | I27: 2b | J27: Y | L27: n
B28: (f) The solution must enforce configurable fatigue management rules. | C28: Y | E28: SX | G28: SX | I28: 2b | J28: Y | L28: n
B29: 5. Unpredictability rules – can automatically fill a roster by selecting one or more employees per product type (e.g. armed guard, service concierge), to form a team assigned to a Task. The following rules shall apply:
B30: (a) no officer shall be rostered with the same Team for more than 1 day consecutively. | C30: P | D30: Need documented process. May require extension. | E30: X | G30: N | H30: To integrate with MASS+ | I30: 2b | L30: n
B31: (b) no officer shall be rostered to the same should be on same demand for more than 1 day consecutively. | C31: Y | E31: X | G31: N | H31: To integrate with MASS+ | I31: 2b | L31: n
B32: 6. Rostering Reserve/Relief employees to fill billable demands – have the capability to automatically roster reserve/relief group of employees into multiple unfilled billable demands without impact on the original reserve/relief shift pattern. | C32: Y | E32: SX | G32: X | H32: Manual Toggle | I32: 2b | J32: Y | L32: n
B33: 7. Split rosters across multiple Cost Centres – have the capability to allow rosters to split across multiple Cost Centres, to allow cross-rostering of employees from one Cost Centre to another to maximise manpower availability. | C33: Y | E33: SX | G33: SX | I33: 2b | J33: Y | L33: n
B34: 8. Blacklist/Whitelist can blacklist/whitelist at various administrative levels e.g., demand/work type, site, client. | C34: Y | D34: Need an extension for blacklisting/whitelisting of specific resources based on defined criteria. | E34: SX | G34: SX | I34: 2b | J34: Y | L34: n
B35: 9. Hard-protect roster slot s. Ensure that shifts which were assigned based on Shift Swap or Self-Bid methods are NOT subject to change when the roster is re-generated. These slots are protected from any automatic change. | C35: Y | E35: SX | G35: SX | H35: Integrate with Cadence | I35: 2b | J35: Y | L35: Y | M35: Cadence
B36: 10. Ability to apply Global Changes according to one or more attributes e.g. change shift pattern of all employees belonging to a single product/Position/level type. | C36: Y | E36: SX | G36: SX | I36: 2b | J36: Y | L36: n
B37: Demand Creation | C37: Fulfil Certis' Requirements? (Yes/No/Partial) | D37: Remarks
A38: i. | B38: Please provide a detailed description of the various types of demand within the Workforce Scheduling (NGRS) system. | C38: Y | D38: Demand can be created ad-hoc, repeating and through integration. The types of demand are unlimited as the demand can be tagged with customizable and/or definable labels to categorize it. There is no limit on the "types" of demand within the system. | E38: X | G38: N | H38: Just show E2E process only | I38: 2b
A39: ii | B39: Please outline the end-to-end process for configuring new demand within the Workforce Scheduling (NGRS) system, including but not limited to parameters such as 24/7 operations, allowances, time, headcount, gender, nationality, and skillsets | C39: Y | D39: When demand is created, can have restrictions or mandatory qualification issued with that demand. | E39: X | G39: N | H39: Just show E2E process only | I39: 2b
A40: iii. | B40: The system must have functionality that allows for the creation of backdated work orders, including the ability to create and send them for billing within a 24-hour timeframe | C40: Y | E40: SX | G40: SX | I40: 2b | J40: Y | L40: n
A41: iv. | B41: Please specify the duration for which the roster allows updates to backdated entries | C41: Y | D41: Limits can be put based on Certis' needs. | E41: SX | G41: SX | I41: 2b | J41: Y | K41: Limits can be put based on Certis' needs. | L41: n
A42: v | B42: The system must support the capability to accommodate last-minute changes and ensure updates are reflected within the same day. | C42: Y | E42: X | G42: X | I42: 2b | J42: Y | L42: n
...

Sheet 2c. Delivery
A1: 2c. | B1: Delivery. In terms of delivering filled rosters and supporting day-of-ops, the Software shall: | C1: Fulfil Certis' Requirements? (Yes/No/Partial) | D1: Remarks | E1: SG (X if required SX Showstopper) | F1: AU (X if required) | G1: Revised Requirements | H1: Certis Remarks | I1: Indicator | J1: Response (Yes/No/Partial) | K1: Remarks | L1: Cadence Related
A2: i. | B2: Basic Scheduling Capabilities | F2: X
B3: The solution must support the creation, modification, and publication of employee rosters for individuals or groups across multiple operational units with varying business rules. It must accommodate updates to draft or published rosters over different timeframes (e.g., from a specific date onward or for a defined period) to maintain flexibility and operational continuity. | C3: Y | E3: SX | G3: SX | I3: 2c | J3: Y | L3: n
B4: The system must support the creation and assignment of both simple and complex work patterns. These patterns should be applicable to individual employees or groups, with flexibility to accommodate varied roles, sites, or classifications. | C4: Y | E4: SX | G4: SX | I4: 2c | J4: Y | L4: n
B5: The solution must provide visibility into forecasted demand, roster shortfalls, and unallocated shifts, enabling proactive workforce planning and timely resolution of coverage gaps. | C5: Y | D5: When viewing the roster, visual notifications are displayed for open slots, and messages are displayed below the roster showing how many slots were created and filled. | E5: SX | G5: SX | I5: 2c | J5: Y | L5: n
B6: The system must support the generation of cost-effective rosters by forecasting roster costs, including allowances, loadings, and overtime. It should promote fair and equitable distribution of work hours across the workforce, ensuring minimum target hours are met while reducing reliance on overtime. Where applicable, the system should highlight scheduling options with or without rule breaks to support informed decision-making. | C6: Y | E6: X | G6: X | I6: 2c | J6: P | K6: Some elements are included here, but proactive costing before rosters are created creates an exponentially complex problem to solve while keeping the software fast. Roster costing is usually once roster is assigned and/or published, not beforehand. | L6: n
B7: The solution must support rule-driven automation for shift allocation, considering factors such as skills, availability, cost, qualifications, hours worked, and policy compliance. It should allow prioritisation of best-fit candidates for each shift based on configurable criteria. | C7: Y | E7: SX | G7: SX | I7: 2c | J7: P | K7: Same as above, cost inclusion during this process (especially since there are such a volume of compliance rules and categories, becomes an exponentially large problem space to solve). Most of the other elements are taken into account, but cost is challenging while keeping the solution optimized for speed. As technology advances, this will likely change and machines will likely be able to solve larger problem spaces in a shorter amount of time. | L7: n
B8: Create and assign work patterns to an individual employee or to a group of employees in mass (e.g., to all officers at the same site) | C8: Y | E8: SX | G8: SX | I8: 2c | J8: Y | L8: n
B9: Auto assign work patterns from an interface The solution must support the import and update of rosters via external sources (e.g., spreadsheets or third-party systems), allowing flexibility in how rosters are created or maintained. | C9: Y | D9: Work patterns can be assigned on logging into our solution from your PC, Laptop or tablet | E9: X | G9: X | H9: Allow Mass Upload | I9: 2c | J9: Y | L9: n
B10: The system must provide real-time notifications to roster planners for actions such as unallocated shifts, absences, no-shows, and policy violations (e.g., overtime breaches), supported by configurable workflows for approvals or overrides | C10: Y | D10: The ability to manage baseline staffing requirements is supported in SAP F&S by defining staffing headcount requirements and shifts into models. | E10: X | G10: X | I10: 2c | J10: Y | K10: Not exactly notifications but visual indicators and clear visuals that ensure that everything remains compliant. Functionally achieving the same thing. The issue with notifications at volume is that they become overwhelming and users suffer from "notification fatigue" where they no longer pay attention to them. | L10: n
B11: 11. Optimize schedules to reduce overtime and fill unplanned gaps with qualified employees. | C11: Y | E11: X | G11: X | I11: 2c | J11: Y | L11: n
